Workbook

Sheet Bar Charts
B6: Marbles | K6: Marbles
B7: Red | C7: =RANDBETWEEN(1,100) -> 28 | K7: Blue | L7: =C8 -> 74
B8: Blue | C8: =RANDBETWEEN(1,100) -> 74 | K8: Green | L8: =C9 -> 46
B9: Green | C9: =RANDBETWEEN(1,100) -> 46 | K9: Yellow | L9: =C10 -> 58
B10: Yellow | C10: =RANDBETWEEN(1,100) -> 58 | K10: Red | L10: =C7 -> 28
I18: A bar chart can represent the frequency of a single categorical variable. Notice that the order of the categories is not important, it is only the height of the bars that matters.
D27: Video For this.
D28: (Same video)

Sheet Height Data
B1: ='Histogram (Unequal Bin Widths)'!B2 -> Heights | C1: Y
B2: ='Histogram (Unequal Bin Widths)'!B3 -> 66.242934 | C2: 0.1
B3: ='Histogram (Unequal Bin Widths)'!B4 -> 64.733945 | C3: 0.1 | F3: Here the height data is simply ploted along the x-axis. You can see how it bunches up, i.e., becomes denser toward th center and less dense towards the ends. It is this "density" that a histogram is meant to visualize. The units for density would be "some number of people per inch (in height)" or relative density would be "some percentage of the data (the population) per inch."
B4: ='Histogram (Unequal Bin Widths)'!B5 -> 66.205359 | C4: 0.1
B5: ='Histogram (Unequal Bin Widths)'!B6 -> 70.566313 | C5: 0.1
B6: ='Histogram (Unequal Bin Widths)'!B7 -> 63.835344 | C6: 0.1
B7: ='Histogram (Unequal Bin Widths)'!B8 -> 68.125398 | C7: 0.1
B8: ='Histogram (Unequal Bin Widths)'!B9 -> 70.40694 | C8: 0.1
B9: ='Histogram (Unequal Bin Widths)'!B10 -> 68.7583 | C9: 0.1
B10: ='Histogram (Unequal Bin Widths)'!B11 -> 68.052734 | C10: 0.1
B11: ='Histogram (Unequal Bin Widths)'!B12 -> 60.337737 | C11: 0.1
B12: ='Histogram (Unequal Bin Widths)'!B13 -> 66.232521 | C12: 0.1
B13: ='Histogram (Unequal Bin Widths)'!B14 -> 66.244666 | C13: 0.1
B14: ='Histogram (Unequal Bin Widths)'!B15 -> 72.926829 | C14: 0.1
B15: ='Histogram (Unequal Bin Widths)'!B16 -> 70.680988 | C15: 0.1
... B17: ='Histogram (Unequal Bin Widths)'!B18 -> 66.520815 | C17: 0.1
B18: ='Histogram (Unequal Bin Widths)'!B19 -> 65.799904 | C18: 0.1 | F18: Heights between 66" and 68" : | I18: =COUNTIFS(B:B,"<=68",B:B,">66") -> 29
B19: ='Histogram (Unequal Bin Widths)'!B20 -> 63.813916 | C19: 0.1 | F19: Percent of heights between 66" and 68" : | I19: =I18/COUNT(B:B) -> 0.23770492
B20: ='Histogram (Unequal Bin Widths)'!B21 -> 64.136402 | C20: 0.1 | F20: Frequency per inch : | I20: =I18/2 -> 14.5
B21: ='Histogram (Unequal Bin Widths)'!B22 -> 62.786435 | C21: 0.1 | F21: Relative Frequency per inch : | I21: =I19/2 -> 0.11885246
B22: ='Histogram (Unequal Bin Widths)'!B23 -> 69.568649 | C22: 0.1
B23: ='Histogram (Unequal Bin Widths)'!B24 -> 64.317415 | C23: 0.1 | F23: ="The density is "&I20&" people (data points) per inch on the interval from 66 to 68 inches of height. While the relative density is "&ROUND(I21*100,2)&"% of the people per inch of height on the same interval." -> The density is 14.5 people (data points) per inch on the interval from 66 to 68 inches of height. While the relative density is 11.89% of the people per inch of height on the same interval.
B24: ='Histogram (Unequal Bin Widths)'!B25 -> 66.061559 | C24: 0.1
B25: ='Histogram (Unequal Bin Widths)'!B26 -> 65.765903 | C25: 0.1
B26: ='Histogram (Unequal Bin Widths)'!B27 -> 66.820492 | C26: 0.1
B27: ='Histogram (Unequal Bin Widths)'!B28 -> 68.263157 | C27: 0.1
B28: ='Histogram (Unequal Bin Widths)'!B29 -> 63.751664 | C28: 0.1
B29: ='Histogram (Unequal Bin Widths)'!B30 -> 61.139526 | C29: 0.1 | H29: Video For this.
B30: ='Histogram (Unequal Bin Widths)'!B31 -> 61.832625 | C30: 0.1 | H30: (Same video)
B31: ='Histogram (Unequal Bin Widths)'!B32 -> 64.458156 | C31: 0.1
B32: ='Histogram (Unequal Bin Widths)'!B33 -> 71.436238 | C32: 0.1
B33: ='Histogram (Unequal Bin Widths)'!B34 -> 70.380261 | C33: 0.1
B34: ='Histogram (Unequal Bin Widths)'!B35 -> 67.958563 | C34: 0.1
B35: ='Histogram (Unequal Bin Widths)'!B36 -> 67.050559 | C35: 0.1
B36: ='Histogram (Unequal Bin Widths)'!B37 -> 67.724337 | C36: 0.1
B37: ='Histogram (Unequal Bin Widths)'!B38 -> 62.770846 | C37: 0.1
B38: ='Histogram (Unequal Bin Widths)'!B39 -> 62.293042 | C38: 0.1
B39: ='Histogram (Unequal Bin Widths)'!B40 -> 65.536564 | C39: 0.1
B40: ='Histogram (Unequal Bin Widths)'!B41 -> 67.207746 | C40: 0.1
B41: ='Histogram (Unequal Bin Widths)'!B42 -> 62.54737 | C41: 0.1
...

Sheet Almost Histogram
B2: Heights | E2: Bin Upper Boundary | F2: Frequency | G2: Relative Frequency | H2: Labels
B3: =_xlfn.NORM.INV(RAND(),66,3) -> 66.242934
B4: =_xlfn.NORM.INV(RAND(),66,3) -> 64.733945 | C4: Max = | D4: =MAX(B:B) -> 72.965816 | E4: =ROUND(D5,1)+D6 -> 61.6 | F4: {=FREQUENCY(B:B,E4:E12)} -> 8 | G4: {=_xlfn.ANCHORARRAY(F4)/COUNT(B:B)} -> 0.06557377 | H4: =(D5+E4)/2 -> 60.968869
B5: =_xlfn.NORM.INV(RAND(),66,3) -> 66.205359 | C5: Min = | D5: =MIN(B:B) -> 60.337737 | E5: =E4+D$6 -> 62.9 | F5: 13 | G5: 0.10655738 | H5: =(E4+E5)/2 -> 62.25
B6: =_xlfn.NORM.INV(RAND(),66,3) -> 70.566313 | C6: Bin width = | D6: =ROUNDUP((D4-D5)/10,1) -> 1.3 | E6: =E5+D$6 -> 64.2 | F6: 17 | G6: 0.13934426 | H6: =(E5+E6)/2 -> 63.55 | P6: ="In a frequency histogram the area of a region should correspond to the number of points on the x-axis lying in that region. This chart, which is often called a histogram, is really still not quite a histogram. Take one of the bars. The area of the bar is "&D6*F9&", but the number of data points represented by the bar is "&F9&"." -> In a frequency histogram the area of a region should correspond to the number of points on the x-axis lying in that region. This chart, which is often called a histogram, is really still not quite a histogram. Take one of the bars. The area of the bar is 26, but the number of data points represented by the bar is 20.
B7: =_xlfn.NORM.INV(RAND(),66,3) -> 63.835344 | E7: =E6+D$6 -> 65.5 | F7: 19 | G7: 0.1557377 | H7: =(E6+E7)/2 -> 64.85
B8: =_xlfn.NORM.INV(RAND(),66,3) -> 68.125398 | E8: =E7+D$6 -> 66.8 | F8: 17 | G8: 0.13934426 | H8: =(E7+E8)/2 -> 66.15
B9: =_xlfn.NORM.INV(RAND(),66,3) -> 70.40694 | E9: =E8+D$6 -> 68.1 | F9: 20 | G9: 0.16393443 | H9: =(E8+E9)/2 -> 67.45
B10: =_xlfn.NORM.INV(RAND(),66,3) -> 68.7583 | E10: =E9+D$6 -> 69.4 | F10: 15 | G10: 0.12295082 | H10: =(E9+E10)/2 -> 68.75
B11: =_xlfn.NORM.INV(RAND(),66,3) -> 68.052734 | E11: =E10+D$6 -> 70.7 | F11: 10 | G11: 0.081967213 | H11: =(E10+E11)/2 -> 70.05
B12: =_xlfn.NORM.INV(RAND(),66,3) -> 60.337737 | E12: =E11+D$6 -> 72 | F12: 1 | G12: 0.0081967213 | H12: =(E11+E12)/2 -> 71.35
B13: =_xlfn.NORM.INV(RAND(),66,3) -> 66.232521 | E13: =E12+D$6 -> 73.3 | F13: 2 | G13: 0.016393443 | H13: =(E12+E13)/2 -> 72.65
B14: =_xlfn.NORM.INV(RAND(),66,3) -> 66.244666 | E14: Totals | F14: =SUM(F4:F13) -> 122 | G14: =SUM(G4:G13) -> 1
B15: =_xlfn.NORM.INV(RAND(),66,3) -> 72.926829
B16: =_xlfn.NORM.INV(RAND(),66,3) -> 70.680988
B17: =_xlfn.NORM.INV(RAND(),66,3) -> 62.879952 | D17: Note that here the data is numeric and this is what the x-axis represents, you cannot rerange the labels on a histogram.
B18: =_xlfn.NORM.INV(RAND(),66,3) -> 66.520815 | P18: ="In a relative frequency histogram the area of a region should correspond to the percentage of "&"points on the x-axis lying in that region. This chart, which is often called a histogram, is really still not quite a histogram. Take one of the bars again. The area of the bar is "&ROUND(D6*G9*100,2)&"%, but the percentage of data points represented by the bar is "&ROUND(G9*100,2)&"%." -> In a relative frequency histogram the area of a region should correspond to the percentage of points on the x-axis lying in that region. This chart, which is often called a histogram, is really still not quite a histogram. Take one of the bars again. The area of the bar is 21.31%, but the percentage of data points represented by the bar is 16.39%.
B19: =_xlfn.NORM.INV(RAND(),66,3) -> 65.799904
B20: =_xlfn.NORM.INV(RAND(),66,3) -> 63.813916
B21: =_xlfn.NORM.INV(RAND(),66,3) -> 64.136402
B22: =_xlfn.NORM.INV(RAND(),66,3) -> 62.786435
B23: =_xlfn.NORM.INV(RAND(),66,3) -> 69.568649
B24: =_xlfn.NORM.INV(RAND(),66,3) -> 64.317415
B25: =_xlfn.NORM.INV(RAND(),66,3) -> 66.061559
B26: =_xlfn.NORM.INV(RAND(),66,3) -> 65.765903
B27: =_xlfn.NORM.INV(RAND(),66,3) -> 66.820492
B28: =_xlfn.NORM.INV(RAND(),66,3) -> 68.263157
B29: =_xlfn.NORM.INV(RAND(),66,3) -> 63.751664
B30: =_xlfn.NORM.INV(RAND(),66,3) -> 61.139526
... B33: =_xlfn.NORM.INV(RAND(),66,3) -> 71.436238
B34: =_xlfn.NORM.INV(RAND(),66,3) -> 70.380261 | I34: Video For this.
B35: =_xlfn.NORM.INV(RAND(),66,3) -> 67.958563 | I35: (Same video)
B36: =_xlfn.NORM.INV(RAND(),66,3) -> 67.050559
B37: =_xlfn.NORM.INV(RAND(),66,3) -> 67.724337
B38: =_xlfn.NORM.INV(RAND(),66,3) -> 62.770846
B39: =_xlfn.NORM.INV(RAND(),66,3) -> 62.293042
B40: =_xlfn.NORM.INV(RAND(),66,3) -> 65.536564
B41: =_xlfn.NORM.INV(RAND(),66,3) -> 67.207746
B42: =_xlfn.NORM.INV(RAND(),66,3) -> 62.54737
B43: =_xlfn.NORM.INV(RAND(),66,3) -> 69.39214
...

Sheet Histogram (Equal Bin Width)
E1: Bin Upper Boundary | F1: Frequency Density | G1: Relative Frequency Density
B2: Heights
B3: ='Almost Histogram'!B3 -> 66.242934
B4: ='Almost Histogram'!B4 -> 64.733945 | C4: Max = | D4: {='Almost Histogram'!D4:D6} -> 72.965816 | E4: {='Almost Histogram'!E4:E13} -> 61.6 | F4: {=ROUND(FREQUENCY(B3:B124,E4:E13)/D6,2)} -> 6.15 | G4: =F4/COUNT(B:B) -> 0.050409836 | H4: =E4-D6 -> 60.3 | I4: {='Almost Histogram'!H4:H13} -> 60.968869 | P4: ="The area of this bar is "&F9&"×"&D6&"="&ROUND(D6*F9,0)&" which is the frequency for this bin." -> The area of this bar is 15.38×1.3=20 which is the frequency for this bin.
B5: ='Almost Histogram'!B5 -> 66.205359 | C5: Min = | D5: 60.337737 | E5: 62.9 | F5: 10 | G5: =F5/COUNT(B:B) -> 0.081967213 | I5: 62.25
B6: ='Almost Histogram'!B6 -> 70.566313 | C6: Bin width = | D6: 1.3 | E6: 64.2 | F6: 13.08 | G6: =F6/COUNT(B:B) -> 0.10721311 | I6: 63.55
B7: ='Almost Histogram'!B7 -> 63.835344 | E7: 65.5 | F7: 14.62 | G7: =F7/COUNT(B:B) -> 0.11983607 | H7: =E7-D9 -> 65.5 | I7: 64.85
B8: ='Almost Histogram'!B8 -> 68.125398 | E8: 66.8 | F8: 13.08 | G8: =F8/COUNT(B:B) -> 0.10721311 | I8: 66.15
B9: ='Almost Histogram'!B9 -> 70.40694 | E9: 68.1 | F9: 15.38 | G9: =F9/COUNT(B:B) -> 0.12606557 | H9: =E9-D11 -> 68.1 | I9: 67.45 | P9: A histogram represents the frequency distribution or relative frequency distribution of a single numeric variable. In the case that the variable is continuous, there should be no gaps between the bars. The frequency or relative frequency is represented by the area of the bar relative to the graph, not the height of the bar. Notice that you cannot reorder the labels on the x-axis in a histogram.
B10: ='Almost Histogram'!B10 -> 68.7583 | E10: 69.4 | F10: 11.54 | G10: =F10/COUNT(B:B) -> 0.094590164 | I10: 68.75
B11: ='Almost Histogram'!B11 -> 68.052734 | E11: 70.7 | F11: 7.69 | G11: =F11/COUNT(B:B) -> 0.063032787 | H11: =E11-D13 -> 70.7 | I11: 70.05
B12: ='Almost Histogram'!B12 -> 60.337737 | E12: 72 | F12: 0.77 | G12: =F12/COUNT(B:B) -> 0.0063114754 | I12: 71.35
B13: ='Almost Histogram'!B13 -> 66.232521 | E13: 73.3 | F13: 1.54 | G13: =F13/COUNT(B:B) -> 0.012622951 | I13: 72.65
B14: ='Almost Histogram'!B14 -> 66.244666 | F14: 0 | H14: =E13 -> 73.3
B15: ='Almost Histogram'!B15 -> 72.926829 | E15: Totals | F15: =ROUND(SUM(F4:F13)*D6,0) -> 122 | G15: =SUM(G4:G13)*D6 -> 1.000041
B16: ='Almost Histogram'!B16 -> 70.680988
B17: ='Almost Histogram'!B17 -> 62.879952
B18: ='Almost Histogram'!B18 -> 66.520815
B19: ='Almost Histogram'!B19 -> 65.799904
B20: ='Almost Histogram'!B20 -> 63.813916 | P20: The area of this bar is the frequency/relative frequency. In the cases where each bin has the same width, there is no real difference in the "shape" of the histogram between using height or area to represent frequency.
B21: ='Almost Histogram'!B21 -> 64.136402
B22: ='Almost Histogram'!B22 -> 62.786435
B23: ='Almost Histogram'!B23 -> 69.568649
B24: ='Almost Histogram'!B24 -> 64.317415
B25: ='Almost Histogram'!B25 -> 66.061559
B26: ='Almost Histogram'!B26 -> 65.765903
B27: ='Almost Histogram'!B27 -> 66.820492 | P27: ="The area of this bar is "&ROUND(G9*100,2)&"%×"&D6&"="&ROUND(D6*G9*100,2)&"% which is the frequency for this bin." -> The area of this bar is 12.61%×1.3=16.39% which is the frequency for this bin.
B28: ='Almost Histogram'!B28 -> 68.263157
B29: ='Almost Histogram'!B29 -> 63.751664
B30: ='Almost Histogram'!B30 -> 61.139526
B31: ='Almost Histogram'!B31 -> 61.832625
B32: ='Almost Histogram'!B32 -> 64.458156
B33: ='Almost Histogram'!B33 -> 71.436238 | I33: Video For this.
B34: ='Almost Histogram'!B34 -> 70.380261 | I34: (Same video)
B35: ='Almost Histogram'!B35 -> 67.958563
B36: ='Almost Histogram'!B36 -> 67.050559
B37: ='Almost Histogram'!B37 -> 67.724337
B38: ='Almost Histogram'!B38 -> 62.770846
B39: ='Almost Histogram'!B39 -> 62.293042
B40: ='Almost Histogram'!B40 -> 65.536564
...

Sheet Histogram (Unequal Bin Widths)
B2: ='Almost Histogram'!B2 -> Heights | D2: Bin upper boundary | E2: Frequency | F2: Width | G2: Frequency Density
B3: ='Almost Histogram'!B3 -> 66.242934 | C3: 0
B4: ='Almost Histogram'!B4 -> 64.733945 | C4: 0 | D4: ='Histogram (Equal Bin Width)'!E6 -> 64.2 | E4: {=FREQUENCY(B:B,D4:D6)} -> 38 | F4: =D4-E9 -> 3.9 | G4: =E4/F4 -> 9.7435897
B5: ='Almost Histogram'!B5 -> 66.205359 | C5: 0 | D5: ='Histogram (Equal Bin Width)'!E8 -> 66.8 | E5: 36 | F5: =D5-D4 -> 2.6 | G5: =E5/F5 -> 13.846154
B6: ='Almost Histogram'!B6 -> 70.566313 | C6: 0 | D6: ='Histogram (Equal Bin Width)'!E10 -> 69.4 | E6: 35 | F6: =D6-D5 -> 2.6 | G6: =E6/F6 -> 13.461538
B7: ='Almost Histogram'!B7 -> 63.835344 | C7: 0 | D7: ='Histogram (Equal Bin Width)'!E13 -> 73.3 | E7: 13 | F7: =D7-D6 -> 3.9 | G7: =E7/F7 -> 3.3333333
B8: ='Almost Histogram'!B8 -> 68.125398 | C8: 0
B9: ='Almost Histogram'!B9 -> 70.40694 | C9: 0 | D9: start | E9: =ROUND('Almost Histogram'!D5,1) -> 60.3 | F9: 0
B10: ='Almost Histogram'!B10 -> 68.7583 | C10: 0 | E10: =E9 -> 60.3 | F10: =G4 -> 9.7435897
B11: ='Almost Histogram'!B11 -> 68.052734 | C11: 0 | E11: =(E10+E12)/2 -> 62.25 | F11: =F10 -> 9.7435897
B12: ='Almost Histogram'!B12 -> 60.337737 | C12: 0 | E12: =D4 -> 64.2 | F12: =G4 -> 9.7435897
B13: ='Almost Histogram'!B13 -> 66.232521 | C13: 0 | D13: end | E13: =D4 -> 64.2 | F13: 0
B14: ='Almost Histogram'!B14 -> 66.244666 | C14: 0 | D14: start | E14: =D4 -> 64.2 | F14: 0
B15: ='Almost Histogram'!B15 -> 72.926829 | C15: 0 | D15: 6 | E15: =D4 -> 64.2 | F15: =G5 -> 13.846154
B16: ='Almost Histogram'!B16 -> 70.680988 | C16: 0 | E16: =(E15+E17)/2 -> 65.5 | F16: =F15 -> 13.846154
B17: ='Almost Histogram'!B17 -> 62.879952 | C17: 0 | E17: =D5 -> 66.8 | F17: =G5 -> 13.846154
B18: ='Almost Histogram'!B18 -> 66.520815 | C18: 0 | D18: end | E18: =D5 -> 66.8 | F18: 0 | I18: The actual data points are shown. Can you see how the height of the bar corresponds to the density of the data? (Zoom in.) | P18: {="For comparison here is the histogram for the same data with equal bin widths. The first three bins of this are combined into a single bin in the histogram to the left. The binwidth is "&'Histogram (Equal Bin Width)'!D6&":"&CHAR(10)&'Histogram (Equal Bin Width)'!$F$4&"×"&'Histogram (Equal Bin Width)'!$D$6&"+"&'Histogram (Equal Bin Width)'!$F$5&"×"&'Histogram (Equal Bin Width)'!$D$6&"+"&'Histogram (Equal Bin Width)'!$F$6&"×"&'Histogram (Equal Bin Width)'!$D$6&"="&ROUND(SUM('Histogram (Equal Bin Width)'!F4:F6*'Histogram (Equal Bin Width)'!D6),0)} -> For comparison here is the histogram for the same data with equal bin widths. The first three bins of this are combined into a single bin in the histogram to the left. The binwidth is 1.3: 6.15×1.3+10×1.3+13.08×1.3=38
B19: ='Almost Histogram'!B19 -> 65.799904 | C19: 0 | D19: start | E19: =D5 -> 66.8 | F19: 0
B20: ='Almost Histogram'!B20 -> 63.813916 | C20: 0 | E20: =D5 -> 66.8 | F20: =G6 -> 13.461538
B21: ='Almost Histogram'!B21 -> 64.136402 | C21: 0 | E21: =(E20+E22)/2 -> 68.1 | F21: =F20 -> 13.461538
B22: ='Almost Histogram'!B22 -> 62.786435 | C22: 0 | E22: =D6 -> 69.4 | F22: =G6 -> 13.461538
B23: ='Almost Histogram'!B23 -> 69.568649 | C23: 0 | D23: end | E23: =D6 -> 69.4 | F23: 0 | H23: ="Note here that the height of a bar is now the frequency density, in this case the first bar has height "&ROUND(G4,1)&" and a width of "&ROUND(F4,2)&" for a frequency of "&ROUND(G4,1)&"×"&ROUND(F4,2)&" ≈ "&ROUND(F4*G4,1)&"." -> Note here that the height of a bar is now the frequency density, in this case the first bar has height 9.7 and a width of 3.9 for a frequency of 9.7×3.9 ≈ 38.
B24: ='Almost Histogram'!B24 -> 64.317415 | C24: 0 | D24: start | E24: =D6 -> 69.4 | F24: 0
B25: ='Almost Histogram'!B25 -> 66.061559 | C25: 0 | E25: =D6 -> 69.4 | F25: =G7 -> 3.3333333
B26: ='Almost Histogram'!B26 -> 65.765903 | C26: 0 | E26: =(E25+E27)/2 -> 71.35 | F26: =F25 -> 3.3333333
B27: ='Almost Histogram'!B27 -> 66.820492 | C27: 0 | E27: =D7 -> 73.3 | F27: =G7 -> 3.3333333
B28: ='Almost Histogram'!B28 -> 68.263157 | C28: 0 | D28: end | E28: =D7 -> 73.3 | F28: 0
B29: ='Almost Histogram'!B29 -> 63.751664 | C29: 0
B30: ='Almost Histogram'!B30 -> 61.139526 | C30: 0 | I30: Video For this.
B31: ='Almost Histogram'!B31 -> 61.832625 | C31: 0 | I31: (Same video)
B32: ='Almost Histogram'!B32 -> 64.458156 | C32: 0
B33: ='Almost Histogram'!B33 -> 71.436238 | C33: 0
B34: ='Almost Histogram'!B34 -> 70.380261 | C34: 0
B35: ='Almost Histogram'!B35 -> 67.958563 | C35: 0
B36: ='Almost Histogram'!B36 -> 67.050559 | C36: 0
B37: ='Almost Histogram'!B37 -> 67.724337 | C37: 0
B38: ='Almost Histogram'!B38 -> 62.770846 | C38: 0
B39: ='Almost Histogram'!B39 -> 62.293042 | C39: 0
B40: ='Almost Histogram'!B40 -> 65.536564 | C40: 0
B41: ='Almost Histogram'!B41 -> 67.207746 | C41: 0
...
